ValueError
ValueError: dict contains fields not in fieldnames: 'Website', 'Price Level', 'Total Reviews', 'Business Status', 'Phone', 'Email', 'Business Name', 'Latitude', 'Longitude', 'Business Types', 'Rating', 'Address', 'City'

Traceback (most recent call last)
File "/home/runner/workspace/.pythonlibs/lib/python3.11/site-packages/flask/app.py", line 1536, in __call__
return self.wsgi_app(environ, start_response)
       ^^^^^^^^^^^^^^^^^^^^^^^^^^^^^^^^^^^^^^
File "/home/runner/workspace/.pythonlibs/lib/python3.11/site-packages/flask/app.py", line 1514, in wsgi_app
response = self.handle_exception(e)
           ^^^^^^^^^^^^^^^^^^^^^^^^
File "/home/runner/workspace/.pythonlibs/lib/python3.11/site-packages/flask/app.py", line 1511, in wsgi_app
response = self.full_dispatch_request()
           ^^^^^^^^^^^^^^^^^^^^^^^^^^^^
File "/home/runner/workspace/.pythonlibs/lib/python3.11/site-packages/flask/app.py", line 919, in full_dispatch_request
rv = self.handle_user_exception(e)
     ^^^^^^^^^^^^^^^^^^^^^^^^^^^^^
File "/home/runner/workspace/.pythonlibs/lib/python3.11/site-packages/flask/app.py", line 917, in full_dispatch_request
rv = self.dispatch_request()
     ^^^^^^^^^^^^^^^^^^^^^^^
File "/home/runner/workspace/.pythonlibs/lib/python3.11/site-packages/flask/app.py", line 902, in dispatch_request
return self.ensure_sync(self.view_functions[rule.endpoint])(**view_args)  # type: ignore[no-any-return]
       ^^^^^^^^^^^^^^^^^^^^^^^^^^^^^^^^^^^^^^^^^^^^^^^^^^^^^^^^^^^^^^^^^
File "/home/runner/workspace/auth_utils.py", line 31, in decorated_function
return f(*args, **kwargs)
       ^^^^^^^^^^^^^^^^^^
File "/home/runner/workspace/app_flask.py", line 2533, in download_business_csv
writer.writerow(business)
^^^^^^^^^^^^^^^^^^^^^^^^^
File "/nix/store/7d088dip86hlzri9sk0h78b63yfmx0a0-python3-3.11.13/lib/python3.11/csv.py", line 154, in writerow
return self.writer.writerow(self._dict_to_list(rowdict))
                            ^^^^^^^^^^^^^^^^^^^^^^^^^^^
File "/nix/store/7d088dip86hlzri9sk0h78b63yfmx0a0-python3-3.11.13/lib/python3.11/csv.py", line 149, in _dict_to_list
raise ValueError("dict contains fields not in fieldnames: "
^^^^^^^^^^^^^^^^^^^^^^^^^^^^^^^^^^^^^^^^^^^^^^^^^^^^^^^^^^^^^^
ValueError: dict contains fields not in fieldnames: 'Website', 'Price Level', 'Total Reviews', 'Business Status', 'Phone', 'Email', 'Business Name', 'Latitude', 'Longitude', 'Business Types', 'Rating', 'Address', 'City'
The debugger caught an exception in your WSGI application. You can now look at the traceback which led to the error.
To switch between the interactive traceback and the plaintext one, you can click on the "Traceback" headline. From the text traceback you can also create a paste of it.

Brought to you by